<?xml version="1.0"?>
<robot xmlns:xacro="http://www.ros.org/wiki/xacro">

<xacro:macro name="gantry" params="prefix">

    <link name="${prefix}E1">
      <visual name="${prefix}visual_E1">
        <origin xyz="0 0.114805 -0.069116" rpy="1.570796 -1.570796 0"/>
        <geometry>
          <mesh filename="package://gantry/meshes/VIFS42.001.dae" scale="1.0 1.0 1.0"/>
        </geometry>
        <material name="${prefix}01___Default.001"/>
      </visual>
      <collision name="${prefix}collision_E1">
        <origin xyz="0 0.114805 -0.069116" rpy="1.570796 -1.570796 0"/>
        <geometry>
          <mesh filename="package://gantry/meshes/VIFS42.000.dae" scale="1.0 1.0 1.0"/>
        </geometry>
      </collision>
    </link>

    <link name="${prefix}E2">
      <visual name="${prefix}visual_E2">
        <origin xyz="0 0 0" rpy="-3.141593 0 0"/>
        <geometry>
          <mesh filename="package://gantry/meshes/VIFS43.001.dae" scale="1.0 1.0 1.0"/>
        </geometry>
        <material name="${prefix}02___Default.001"/>
      </visual>
      <collision name="${prefix}collision_E2">
        <origin xyz="-0.020567 0.254046 -0.042038" rpy="1.570796 0 0"/>
        <geometry>
          <mesh filename="package://gantry/meshes/Cube.005.dae" scale="0.129538 0.485533 0.188935"/>
        </geometry>
      </collision>
    </link>

    <link name="${prefix}E3">
      <visual name="${prefix}visual_E3">
        <origin xyz="0 0 0" rpy="1.570796 0 0"/>
        <geometry>
          <mesh filename="package://gantry/meshes/VIFS96.dae" scale="1.0 1.0 1.0"/>
        </geometry>
        <material name="${prefix}VMtl98"/>
      </visual>
      <collision name="${prefix}collision_E3">
        <origin xyz="0 0 1.34717" rpy="0 0 0"/>
        <geometry>
          <mesh filename="package://gantry/meshes/Cylinder.dae" scale="0.188288 0.188288 0.188288"/>
        </geometry>
      </collision>
    </link>

    <link name="${prefix}base">
      <visual name="${prefix}visual_base">
        <origin xyz="0 0 0" rpy="1.570796 -1.570796 0"/>
        <geometry>
          <mesh filename="package://gantry/meshes/VIFS01.001.dae" scale="1.0 1.0 1.0"/>
        </geometry>
        <material name="${prefix}03___Default.001"/>
      </visual>
      <collision name="${prefix}collision_base">
        <origin xyz="0 0 0" rpy="1.570796 -1.570796 0"/>
        <geometry>
          <mesh filename="package://gantry/meshes/VIFS01.000.dae" scale="1.0 1.0 1.0"/>
        </geometry>
      </collision>
    </link>

    <link name="${prefix}robot_connection">
    </link>

    <link name="${prefix}root">
    </link>

    <joint name="${prefix}E1" type="prismatic">
      <origin xyz="-2.570369 -0.057403 0.034558" rpy="0 0 0"/>
      <parent link="${prefix}base"/>
      <child link="${prefix}E1"/>
      <axis xyz="0 0 1.0"/>
      <limit lower="-2.0" upper="2.0" effort="1.0" velocity="0"/>
    </joint>

    <joint name="${prefix}E2" type="prismatic">
      <origin xyz="-1.277963 0.430506 -0.476427" rpy="-1.570796 -1.570796 0"/>
      <parent link="${prefix}E1"/>
      <child link="${prefix}E2"/>
      <axis xyz="0 0 1.0"/>
      <limit lower="-2.0" upper="2.0" effort="1.0" velocity="0"/>
    </joint>

    <joint name="${prefix}E3" type="prismatic">
      <origin xyz="-0.164527 0.159154 -0.053205" rpy="1.570796 0 0"/>
      <parent link="${prefix}E2"/>
      <child link="${prefix}E3"/>
      <axis xyz="0 0 1.0"/>
      <limit lower="-2.0" upper="2.0" effort="1.0" velocity="0"/>
    </joint>

    <joint name="${prefix}base" type="fixed">
      <origin xyz="0 0 0" rpy="0 1.570796 0"/>
      <parent link="${prefix}root"/>
      <child link="${prefix}base"/>
    </joint>

    <joint name="${prefix}robot_connection" type="fixed">
      <origin xyz="-0.026405 0.000343 -1.392678" rpy="-3.141593 0 0"/>
      <parent link="${prefix}E3"/>
      <child link="${prefix}robot_connection"/>
    </joint>

    <material name="${prefix}01___Default.001">
      <color rgba="0.1922 0.4588 1.0 1.0"/>
    </material>

    <material name="${prefix}02___Default.001">
      <color rgba="1.0 1.0 1.0 1.0"/>
    </material>

    <material name="${prefix}03___Default.001">
      <color rgba="0.5882 0.5882 0.5882 1.0"/>
    </material>

    <material name="${prefix}VMtl98">
      <color rgba="0.5 0.5 0.5 1.0"/>
    </material>

  </xacro:macro>
</robot>
