<?xml version="1.0"?>
<!-- created with Phobos 0.7 -->
  <robot name="gantry">

    <link name="link_arm">
      <inertial>
        <origin xyz="0 0 0" rpy="0 0 0"/>
        <mass value="100.0"/>
        <inertia ixx="77.157539" ixy="-0.43952" ixz="-0.013708" iyy="77.235046" iyz="-3e-06" izz="1.060431"/>
      </inertial>
      <visual name="visual_arm">
        <origin xyz="0 0 0" rpy="1.570796 0 0"/>
        <geometry>
          <mesh filename="../meshes/VIFS96.stl" scale="1.0 1.0 1.0"/>
        </geometry>
        <material name="VMtl98"/>
      </visual>
      <collision name="collision_arm">
        <origin xyz="0 0 1.34717" rpy="0 0 0"/>
        <geometry>
          <mesh filename="../meshes/Cylinder.stl" scale="0.188288 0.188288 0.188288"/>
        </geometry>
      </collision>
    </link>

    <link name="link_base">
      <visual name="visual_base">
        <origin xyz="0 0 0" rpy="1.570796 -1.570796 0"/>
        <geometry>
          <mesh filename="../meshes/VIFS01.001.stl" scale="1.0 1.0 1.0"/>
        </geometry>
        <material name="03___Default.001"/>
      </visual>
      <collision name="collision_base">
        <origin xyz="0 0 0" rpy="1.570796 -1.570796 0"/>
        <geometry>
          <mesh filename="../meshes/VIFS01.000.stl" scale="1.0 1.0 1.0"/>
        </geometry>
      </collision>
    </link>

    <link name="link_leg">
      <inertial>
        <origin xyz="0 0.114805 -0.069116" rpy="0 0 0"/>
        <mass value="1000.0"/>
        <inertia ixx="1880.551147" ixy="0.000265" ixz="0" iyy="7958.77002" iyz="-13.379694" izz="6216.929688"/>
      </inertial>
      <visual name="visual_leg">
        <origin xyz="0 0.114805 -0.069116" rpy="1.570796 -1.570796 0"/>
        <geometry>
          <mesh filename="../meshes/VIFS42.001.stl" scale="1.0 1.0 1.0"/>
        </geometry>
        <material name="01___Default.001"/>
      </visual>
      <collision name="collision_leg">
        <origin xyz="0.000315 0.114805 -0.069116" rpy="1.570796 -1.570796 0"/>
        <geometry>
          <mesh filename="../meshes/VIFS42.000.stl" scale="1.0 1.0 1.0"/>
        </geometry>
      </collision>
    </link>

    <link name="link_trolley">
      <inertial>
        <origin xyz="0 0 0" rpy="0 0 0"/>
        <mass value="100.0"/>
        <inertia ixx="15.599652" ixy="1.71094" ixz="1.886529" iyy="9.19625" iyz="0.938979" izz="14.022485"/>
      </inertial>
      <visual name="visual_trolley">
        <origin xyz="0 0 0" rpy="-3.141593 0 0"/>
        <geometry>
          <mesh filename="../meshes/VIFS43.001.stl" scale="1.0 1.0 1.0"/>
        </geometry>
        <material name="02___Default.001"/>
      </visual>
      <collision name="collision_trolley">
        <origin xyz="-0.020567 0.254046 -0.042038" rpy="1.570796 0 0"/>
        <geometry>
          <mesh filename="../meshes/Cube.005.stl" scale="0.129538 0.485533 0.188935"/>
        </geometry>
      </collision>
    </link>

    <link name="robot_connection">
    </link>

    <link name="root">
    </link>

    <joint name="link_arm" type="prismatic">
      <origin xyz="-0.164527 -0.651668 -0.053205" rpy="1.570796 0 0"/>
      <parent link="link_trolley"/>
      <child link="link_arm"/>
      <axis xyz="0 0 1.0"/>
      <limit lower="-1.6" upper="0" effort="1.0" velocity="0.55"/>
    </joint>

    <joint name="link_base" type="fixed">
      <origin xyz="0 0 0" rpy="0 1.570796 0"/>
      <parent link="root"/>
      <child link="link_base"/>
    </joint>

    <joint name="link_leg" type="prismatic">
      <origin xyz="-2.570369 -0.057403 0.844145" rpy="0 0 0"/>
      <parent link="link_base"/>
      <child link="link_leg"/>
      <axis xyz="0 0 -1.0"/>
      <limit lower="0" upper="1.54" effort="1.0" velocity="0.5"/>
    </joint>

    <joint name="link_trolley" type="prismatic">
      <origin xyz="-1.277963 2.407403 -0.476427" rpy="-1.570796 -1.570796 0"/>
      <parent link="link_leg"/>
      <child link="link_trolley"/>
      <axis xyz="0 0 -1.0"/>
      <limit lower="0" upper="4.7" effort="1.0" velocity="0.83"/>
    </joint>

    <joint name="robot_connection" type="fixed">
      <origin xyz="-0.026405 0.000343 -1.392678" rpy="-3.141593 0 0"/>
      <parent link="link_arm"/>
      <child link="robot_connection"/>
    </joint>

    <material name="01___Default.001">
      <color rgba="0.1922 0.4588 1.0 1.0"/>
    </material>

    <material name="02___Default.001">
      <color rgba="1.0 1.0 1.0 1.0"/>
    </material>

    <material name="03___Default.001">
      <color rgba="0.5882 0.5882 0.5882 1.0"/>
    </material>

    <material name="VMtl98">
      <color rgba="0.5 0.5 0.5 1.0"/>
    </material>

  </robot>
