<?xml version="1.0" ?>
<!-- =================================================================================== -->
<!-- |    This document was autogenerated by xacro from /home/ivareri/catkin_ws/src/ntnu_robotlab/gantry_support/urdf/gantry_robot.xacro | -->
<!-- |    EDITING THIS FILE BY HAND IS NOT RECOMMENDED                                 | -->
<!-- =================================================================================== -->
<!--Generates a urdf from the macro in gantry_macro.xacro -->
<robot name="gantry" xmlns:xacro="http://www.ros.org/wiki/xacro">
  <!-- created with Phobos 0.7 -->
  <link name="link_arm">
    <inertial>
      <origin rpy="0 0 0" xyz="0 0 0"/>
      <mass value="100.0"/>
      <inertia ixx="77.157539" ixy="-0.43952" ixz="-0.013708" iyy="77.235046" iyz="-3e-06" izz="1.060431"/>
    </inertial>
    <visual name="visual_arm">
      <origin rpy="1.57079632679 0 0" xyz="0 0 0"/>
      <geometry>
        <mesh filename="package://gantry_support/meshes/VIFS96.stl" scale="1.0 1.0 1.0"/>
      </geometry>
      <material name="VMtl98"/>
    </visual>
    <collision name="collision_arm">
      <origin rpy="0 0 0" xyz="0 0 1.34717"/>
      <geometry>
        <mesh filename="package://gantry_support/meshes/Cylinder.stl" scale="0.188288 0.188288 0.188288"/>
      </geometry>
    </collision>
  </link>
  <link name="link_base">
    <visual name="visual_base">
      <origin rpy="1.57079632679 -1.57079632679 0" xyz="0 0 0"/>
      <geometry>
        <mesh filename="package://gantry_support/meshes/VIFS01.001.stl" scale="1.0 1.0 1.0"/>
      </geometry>
      <material name="03___Default.001"/>
    </visual>
    <collision name="collision_base">
      <origin rpy="1.57079632679 -1.57079632679 0" xyz="0 0 0"/>
      <geometry>
        <mesh filename="package://gantry_support/meshes/VIFS01.000.stl" scale="1.0 1.0 1.0"/>
      </geometry>
    </collision>
  </link>
  <link name="link_leg">
    <inertial>
      <origin rpy="0 0 0" xyz="0 0.114805 -0.069116"/>
      <mass value="1000.0"/>
      <inertia ixx="1880.551147" ixy="0.000265" ixz="0" iyy="7958.77002" iyz="-13.379694" izz="6216.929688"/>
    </inertial>
    <visual name="visual_leg">
      <origin rpy="1.57079632679 -1.57079632679 0" xyz="0 0.114805 -0.069116"/>
      <geometry>
        <mesh filename="package://gantry_support/meshes/VIFS42.001.stl" scale="1.0 1.0 1.0"/>
      </geometry>
      <material name="01___Default.001"/>
    </visual>
    <collision name="collision_leg">
      <origin rpy="1.57079632679 -1.57079632679 0" xyz="0.000315 0.114805 -0.069116"/>
      <geometry>
        <mesh filename="package://gantry_support/meshes/VIFS42.000.stl" scale="1.0 1.0 1.0"/>
      </geometry>
    </collision>
  </link>
  <link name="link_trolley">
    <inertial>
      <origin rpy="0 0 0" xyz="0 0 0"/>
      <mass value="100.0"/>
      <inertia ixx="15.599652" ixy="1.71094" ixz="1.886529" iyy="9.19625" iyz="0.938979" izz="14.022485"/>
    </inertial>
    <visual name="visual_trolley">
      <origin rpy="-3.14159265359 0 0" xyz="0 0 0"/>
      <geometry>
        <mesh filename="package://gantry_support/meshes/VIFS43.001.stl" scale="1.0 1.0 1.0"/>
      </geometry>
      <material name="02___Default.001"/>
    </visual>
    <collision name="collision_trolley">
      <origin rpy="1.57079632679 0 0" xyz="-0.020567 0.254046 -0.042038"/>
      <geometry>
        <mesh filename="package://gantry_support/meshes/Cube.005.stl" scale="0.129538 0.485533 0.188935"/>
      </geometry>
    </collision>
  </link>
  <link name="robot_connection">
    </link>
  <link name="root">
    </link>
  <joint name="joint_e3" type="prismatic">
    <origin rpy="1.57079632679 0 0" xyz="-0.164527 -0.651668 -0.053205"/>
    <parent link="link_trolley"/>
    <child link="link_arm"/>
    <axis xyz="0 0 1.0"/>
    <limit effort="1.0" lower="-1.6" upper="0" velocity="0.55"/>
  </joint>
  <joint name="link_base" type="fixed">
    <origin rpy="0 1.57079632679 0" xyz="0 0 0"/>
    <parent link="root"/>
    <child link="link_base"/>
  </joint>
  <joint name="joint_e1" type="prismatic">
    <origin rpy="0 0 0" xyz="-2.570369 -0.057403 0.844145"/>
    <parent link="link_base"/>
    <child link="link_leg"/>
    <axis xyz="0 0 -1.0"/>
    <limit effort="1.0" lower="0" upper="1.54" velocity="0.5"/>
  </joint>
  <joint name="joint_e2" type="prismatic">
    <origin rpy="-1.57079632679 -1.57079632679 0" xyz="-1.277963 2.407403 -0.476427"/>
    <parent link="link_leg"/>
    <child link="link_trolley"/>
    <axis xyz="0 0 -1.0"/>
    <limit effort="1.0" lower="0" upper="4.7" velocity="0.83"/>
  </joint>
  <joint name="robot_connection" type="fixed">
    <origin rpy="-3.14159265359 0 0" xyz="-0.026405 0.000343 -1.392678"/>
    <parent link="link_arm"/>
    <child link="robot_connection"/>
  </joint>
  <material name="01___Default.001">
    <color rgba="0.1922 0.4588 1.0 1.0"/>
  </material>
  <material name="02___Default.001">
    <color rgba="1.0 1.0 1.0 1.0"/>
  </material>
  <material name="03___Default.001">
    <color rgba="0.5882 0.5882 0.5882 1.0"/>
  </material>
  <material name="VMtl98">
    <color rgba="0.5 0.5 0.5 1.0"/>
  </material>
  <!-- LINKS -->
  <!-- base link -->
  <link name="base_link">
    <inertial>
      <origin rpy="0 0 0" xyz="0 0 0"/>
      <mass value="2"/>
      <inertia ixx="0.01" ixy="0" ixz="0" iyy="0.01" iyz="0" izz="0.01"/>
    </inertial>
    <visual>
      <origin rpy="0 0 0" xyz="0 0 0"/>
      <geometry>
        <mesh filename="package://kuka_kr16_support/meshes/kr16_2/visual/base_link.dae"/>
      </geometry>
    </visual>
    <collision>
      <origin rpy="0 0 0" xyz="0 0 0"/>
      <geometry>
        <mesh filename="package://kuka_kr16_support/meshes/kr16_2/collision/base_link.stl"/>
      </geometry>
    </collision>
  </link>
  <!-- link 1 (A1) -->
  <link name="link_1">
    <inertial>
      <origin rpy="0 0 0" xyz="0 0 0"/>
      <mass value="2"/>
      <inertia ixx="0.01" ixy="0" ixz="0" iyy="0.01" iyz="0" izz="0.01"/>
    </inertial>
    <visual>
      <origin rpy="0 0 0" xyz="0 0 0"/>
      <geometry>
        <mesh filename="package://kuka_kr16_support/meshes/kr16_2/visual/link_1.dae"/>
      </geometry>
    </visual>
    <collision>
      <origin rpy="0 0 0" xyz="0 0 0"/>
      <geometry>
        <mesh filename="package://kuka_kr16_support/meshes/kr16_2/collision/link_1.stl"/>
      </geometry>
    </collision>
  </link>
  <!-- link 2 -->
  <link name="link_2">
    <inertial>
      <origin rpy="0 0 0" xyz="0 0 0"/>
      <mass value="2"/>
      <inertia ixx="0.01" ixy="0" ixz="0" iyy="0.01" iyz="0" izz="0.01"/>
    </inertial>
    <visual>
      <origin rpy="0 0 0" xyz="0 0 0"/>
      <geometry>
        <mesh filename="package://kuka_kr16_support/meshes/kr16_2/visual/link_2.dae"/>
      </geometry>
    </visual>
    <collision>
      <origin rpy="0 0 0" xyz="0 0 0"/>
      <geometry>
        <mesh filename="package://kuka_kr16_support/meshes/kr16_2/collision/link_2.stl"/>
      </geometry>
    </collision>
  </link>
  <!-- link 3 -->
  <link name="link_3">
    <inertial>
      <origin rpy="0 0 0" xyz="0 0 0"/>
      <mass value="2"/>
      <inertia ixx="0.01" ixy="0" ixz="0" iyy="0.01" iyz="0" izz="0.01"/>
    </inertial>
    <visual>
      <origin rpy="0 0 0" xyz="0 0 0"/>
      <geometry>
        <mesh filename="package://kuka_kr16_support/meshes/kr16_2/visual/link_3.dae"/>
      </geometry>
    </visual>
    <collision>
      <origin rpy="0 0 0" xyz="0 0 0"/>
      <geometry>
        <mesh filename="package://kuka_kr16_support/meshes/kr16_2/collision/link_3.stl"/>
      </geometry>
    </collision>
  </link>
  <!-- link 4 -->
  <link name="link_4">
    <inertial>
      <origin rpy="0 0 0" xyz="0 0 0"/>
      <mass value="2"/>
      <inertia ixx="0.01" ixy="0" ixz="0" iyy="0.01" iyz="0" izz="0.01"/>
    </inertial>
    <visual>
      <origin rpy="0 0 0" xyz="0 0 0"/>
      <geometry>
        <mesh filename="package://kuka_kr16_support/meshes/kr16_2/visual/link_4.dae"/>
      </geometry>
    </visual>
    <collision>
      <origin rpy="0 0 0" xyz="0 0 0"/>
      <geometry>
        <mesh filename="package://kuka_kr16_support/meshes/kr16_2/collision/link_4.stl"/>
      </geometry>
    </collision>
  </link>
  <!-- link 5 -->
  <link name="link_5">
    <inertial>
      <origin rpy="0 0 0" xyz="0 0 0"/>
      <mass value="2"/>
      <inertia ixx="0.01" ixy="0" ixz="0" iyy="0.01" iyz="0" izz="0.01"/>
    </inertial>
    <visual>
      <origin rpy="0 0 0" xyz="0 0 0"/>
      <geometry>
        <mesh filename="package://kuka_kr16_support/meshes/kr16_2/visual/link_5.dae"/>
      </geometry>
    </visual>
    <collision>
      <origin rpy="0 0 0" xyz="0 0 0"/>
      <geometry>
        <mesh filename="package://kuka_kr16_support/meshes/kr16_2/collision/link_5.stl"/>
      </geometry>
    </collision>
  </link>
  <!-- link 6 -->
  <link name="link_6">
    <inertial>
      <origin rpy="0 0 0" xyz="0 0 0"/>
      <mass value="2"/>
      <inertia ixx="0.01" ixy="0" ixz="0" iyy="0.01" iyz="0" izz="0.01"/>
    </inertial>
    <visual>
      <origin rpy="0 0 0" xyz="0 0 0"/>
      <geometry>
        <mesh filename="package://kuka_kr16_support/meshes/kr16_2/visual/link_6.dae"/>
      </geometry>
    </visual>
    <collision>
      <origin rpy="0 0 0" xyz="0 0 0"/>
      <geometry>
        <mesh filename="package://kuka_kr16_support/meshes/kr16_2/collision/link_6.stl"/>
      </geometry>
    </collision>
  </link>
  <!-- tool 0 -->
  <!-- This frame corresponds to the $FLANGE coordinate system in KUKA KRC controllers. -->
  <link name="tool0"/>
  <!-- END LINKS -->
  <!-- JOINTS -->
  <!-- joint 1 (A1) -->
  <joint name="joint_a1" type="revolute">
    <origin rpy="0 0 0" xyz="0 0 0.675"/>
    <parent link="base_link"/>
    <child link="link_1"/>
    <axis xyz="0 0 -1"/>
    <limit effort="0" lower="-3.22885911619" upper="3.22885911619" velocity="2.72271363311"/>
  </joint>
  <!-- joint 2 (A2) -->
  <joint name="joint_a2" type="revolute">
    <origin rpy="0 0 0" xyz="0.26 0 0"/>
    <parent link="link_1"/>
    <child link="link_2"/>
    <axis xyz="0 1 0"/>
    <limit effort="0" lower="-2.70526034059" upper="0.610865238198" velocity="2.72271363311"/>
  </joint>
  <!-- joint 3 (A3) -->
  <joint name="joint_a3" type="revolute">
    <origin rpy="0 0 0" xyz="0.68 0 0"/>
    <parent link="link_2"/>
    <child link="link_3"/>
    <axis xyz="0 1 0"/>
    <limit effort="0" lower="-2.26892802759" upper="2.68780704807" velocity="2.72271363311"/>
  </joint>
  <!-- joint 4 (A4) -->
  <joint name="joint_a4" type="revolute">
    <origin rpy="0 0 0" xyz="0.67 0 -0.035"/>
    <parent link="link_3"/>
    <child link="link_4"/>
    <axis xyz="-1 0 0"/>
    <limit effort="0" lower="-6.10865238198" upper="6.10865238198" velocity="5.75958653158"/>
  </joint>
  <!-- joint 5 (A5) -->
  <joint name="joint_a5" type="revolute">
    <origin rpy="0 0 0" xyz="0 0 0"/>
    <parent link="link_4"/>
    <child link="link_5"/>
    <axis xyz="0 1 0"/>
    <limit effort="0" lower="-2.26892802759" upper="2.26892802759" velocity="5.75958653158"/>
  </joint>
  <!-- joint 6 (A6) -->
  <joint name="joint_a6" type="revolute">
    <origin rpy="0 0 0" xyz="0 0 0"/>
    <parent link="link_5"/>
    <child link="link_6"/>
    <axis xyz="-1 0 0"/>
    <limit effort="0" lower="-6.10865238198" upper="6.10865238198" velocity="10.7337748998"/>
  </joint>
  <!-- tool frame - fixed frame -->
  <joint name="joint_a6-tool0" type="fixed">
    <parent link="link_6"/>
    <child link="tool0"/>
    <origin rpy="0 1.57079632679 0" xyz="0.158 0 0"/>
  </joint>
  <!-- END JOINTS -->
  <!-- ROS base_link to KUKA $ROBROOT coordinate system transform -->
  <link name="base"/>
  <joint name="base_link-base" type="fixed">
    <origin rpy="0 0 0" xyz="0 0 0"/>
    <parent link="base_link"/>
    <child link="base"/>
  </joint>
  <joint name="gantry_robot" type="fixed">
    <origin rpy="0 0 1.57079632679" xyz="0 0 0"/>
    <parent link="robot_connection"/>
    <child link="base_link"/>
  </joint>
</robot>

